<?xml version="1.0" ?>
<!-- =================================================================================== -->
<!-- |    This document was autogenerated by xacro from robot.xacro                    | -->
<!-- |    EDITING THIS FILE BY HAND IS NOT RECOMMENDED                                 | -->
<!-- =================================================================================== -->
<robot name="swingarm_v2">
  <link name="world"/>
  <link name="base_link">
    <inertial>
      <origin rpy="0 0 0" xyz="0.0 0.0 0.028"/>
      <mass value="0.498"/>
      <inertia ixx="0.0" ixy="4.484e-08" ixz="-8.322e-07" iyy="0.0" iyz="1.422e-10" izz="0.0"/>
    </inertial>
    <visual>
      <origin rpy="0 0 0" xyz="0 0 0"/>
      <geometry>
        <mesh filename="package://swingarm_v2_config/description/meshes/base_link.stl" scale="1 1 1"/>
      </geometry>
    </visual>
    <collision>
      <origin rpy="0 0 0" xyz="0 0 0"/>
      <geometry>
        <mesh filename="package://swingarm_v2_config/description/meshes/base_link.stl" scale="1 1 1"/>
      </geometry>
    </collision>
  </link>
  <link name="link1">
    <inertial>
      <origin rpy="0 0 0" xyz="0.0 -0.002 0.031"/>
      <mass value="0.432"/>
      <inertia ixx="0.0" ixy="7.814e-07" ixz="-7.29e-09" iyy="0.0" iyz="-6.728e-07" izz="0.0"/>
    </inertial>
    <visual>
      <origin rpy="0 0 0" xyz="0 0 0"/>
      <geometry>
        <mesh filename="package://swingarm_v2_config/description/meshes/link1.stl" scale="1 1 1"/>
      </geometry>
    </visual>
    <collision>
      <origin rpy="0 0 0" xyz="0 0 0"/>
      <geometry>
        <mesh filename="package://swingarm_v2_config/description/meshes/link1.stl" scale="1 1 1"/>
      </geometry>
    </collision>
  </link>
  <link name="link2">
    <inertial>
      <origin rpy="0 0 0" xyz="-0.055 -0.005 0.0"/>
      <mass value="0.553"/>
      <inertia ixx="0.0" ixy="0.0" ixz="0.0" iyy="0.0" iyz="-3.207e-08" izz="0.0"/>
    </inertial>
    <visual>
      <origin rpy="0 0 0" xyz="0 0 0"/>
      <geometry>
        <mesh filename="package://swingarm_v2_config/description/meshes/link2.stl" scale="1 1 1"/>
      </geometry>
    </visual>
    <collision>
      <origin rpy="0 0 0" xyz="0 0 0"/>
      <geometry>
        <mesh filename="package://swingarm_v2_config/description/meshes/link2.stl" scale="1 1 1"/>
      </geometry>
    </collision>
  </link>
  <link name="link3">
    <inertial>
      <origin rpy="0 0 0" xyz="-0.112 0.001 -0.015"/>
      <mass value="0.952"/>
      <inertia ixx="0.001" ixy="4.317e-05" ixz="0.0" iyy="0.003" iyz="-2.507e-05" izz="0.003"/>
    </inertial>
    <visual>
      <origin rpy="0 0 0" xyz="0 0 0"/>
      <geometry>
        <mesh filename="package://swingarm_v2_config/description/meshes/link3.stl" scale="1 1 1"/>
      </geometry>
    </visual>
    <collision>
      <origin rpy="0 0 0" xyz="0 0 0"/>
      <geometry>
        <mesh filename="package://swingarm_v2_config/description/meshes/link3.stl" scale="1 1 1"/>
      </geometry>
    </collision>
  </link>
  <link name="link4">
    <inertial>
      <origin rpy="0 0 0" xyz="0.048 -0.004 0.014"/>
      <mass value="0.48"/>
      <inertia ixx="0.0" ixy="-8.407e-05" ixz="-3.672e-05" iyy="0.0" iyz="-2.468e-05" izz="0.0"/>
    </inertial>
    <visual>
      <origin rpy="0 0.286 0" xyz="0 0 0"/>
      <geometry>
        <mesh filename="package://swingarm_v2_config/description/meshes/link4.stl" scale="1 1 1"/>
      </geometry>
    </visual>
    <collision>
      <origin rpy="0 0.286 0" xyz="0 0 0"/>
      <geometry>
        <mesh filename="package://swingarm_v2_config/description/meshes/link4.stl" scale="1 1 1"/>
      </geometry>
    </collision>
  </link>
  <link name="link5">
    <inertial>
      <origin rpy="0 0 0" xyz="0.089 0.0 0.004"/>
      <mass value="0.612"/>
      <inertia ixx="0.0" ixy="-3.674e-06" ixz="0.0" iyy="0.001" iyz="1.449e-07" izz="0.001"/>
    </inertial>
    <visual>
      <origin rpy="0 0 0" xyz="0 0 0"/>
      <geometry>
        <mesh filename="package://swingarm_v2_config/description/meshes/link5.stl" scale="1 1 1"/>
      </geometry>
    </visual>
    <collision>
      <origin rpy="0 0 0" xyz="0 0 0"/>
      <geometry>
        <mesh filename="package://swingarm_v2_config/description/meshes/link5.stl" scale="1 1 1"/>
      </geometry>
    </collision>
  </link>
  <link name="link6">
    <inertial>
      <origin rpy="0 0 0" xyz="0.05 0.02 0.0"/>
      <mass value="0.484"/>
      <inertia ixx="0.0" ixy="-6.597e-05" ixz="-2.378e-08" iyy="0.0" iyz="1.028e-07" izz="0.0"/>
    </inertial>
    <visual>
      <origin rpy="0 0 0" xyz="0 -0.023 0"/>
      <geometry>
        <mesh filename="package://swingarm_v2_config/description/meshes/link6.stl" scale="1 1 1"/>
      </geometry>
    </visual>
    <collision>
      <origin rpy="0 0 0" xyz="0 -0.023 0"/>
      <geometry>
        <mesh filename="package://swingarm_v2_config/description/meshes/link6.stl" scale="1 1 1"/>
      </geometry>
    </collision>
  </link>
  <link name="link7">
    <inertial>
      <origin rpy="0 0 0" xyz="0.005 0.0 0.001"/>
      <mass value="0.105"/>
      <inertia ixx="2.296e-05" ixy="0.0" ixz="-5.572e-09" iyy="1.383e-05" iyz="0.0" izz="1.089e-05"/>
    </inertial>
    <visual>
      <origin rpy="0 0 0" xyz="0 0 0"/>
      <geometry>
        <mesh filename="package://swingarm_v2_config/description/meshes/link7.stl" scale="1 1 1"/>
      </geometry>
    </visual>
    <collision>
      <origin rpy="0 0 0" xyz="0 0 0"/>
      <geometry>
        <mesh filename="package://swingarm_v2_config/description/meshes/link7.stl" scale="1 1 1"/>
      </geometry>
    </collision>
  </link>
  <joint name="fixed_world" type="fixed">
    <origin rpy="0 0 0" xyz="0 0 0"/>
    <parent link="world"/>
    <child link="base_link"/>
  </joint>
  <joint name="joint1" type="revolute">
    <origin rpy="0 0 0" xyz="0 0 0.0565"/>
    <parent link="base_link"/>
    <child link="link1"/>
    <axis xyz="0 0 1"/>
    <limit effort="30" lower="-1.57" upper="1.57" velocity="1.5"/>
  </joint>
  <joint name="joint2" type="revolute">
    <origin rpy="0 0 0" xyz="0 0 0.0335"/>
    <parent link="link1"/>
    <child link="link2"/>
    <axis xyz="0 1 0"/>
    <limit effort="30" lower="0" upper="3.14" velocity="1.5"/>
  </joint>
  <joint name="joint3" type="revolute">
    <origin rpy="0 0 0" xyz="-0.095 0 0"/>
    <parent link="link2"/>
    <child link="link3"/>
    <axis xyz="1 0 0"/>
    <limit effort="30" lower="-3.14" upper="0.0" velocity="1.5"/>
  </joint>
  <joint name="joint4" type="revolute">
    <origin rpy="0 -0.286 0" xyz="-0.155 0 0"/>
    <parent link="link3"/>
    <child link="link4"/>
    <axis xyz="0 1 0"/>
    <limit effort="10" lower="-1.1" upper="0.3" velocity="1.5"/>
  </joint>
  <joint name="joint5" type="revolute">
    <origin rpy="0  0  0" xyz="0.0845 0 0"/>
    <parent link="link4"/>
    <child link="link5"/>
    <axis xyz="1 0 0"/>
    <limit effort="10" lower="-0.785" upper="0.785" velocity="1.5"/>
  </joint>
  <joint name="joint6" type="revolute">
    <origin rpy="0 0.286 0" xyz="0.1177 0 0"/>
    <parent link="link5"/>
    <child link="link6"/>
    <axis xyz="0 1 0"/>
    <limit effort="10" lower="-1.57" upper="1.57" velocity="1.5"/>
  </joint>
  <joint name="joint7" type="revolute">
    <origin rpy="0 0 0" xyz="0.0845 0 0"/>
    <parent link="link6"/>
    <child link="link7"/>
    <axis xyz="1 0 0"/>
    <limit effort="10" lower="-1.57" upper="1.57" velocity="1.5"/>
  </joint>
  <transmission name="joint1_tran">
    <type>transmission_interface/SimpleTransmission</type>
    <joint name="joint1">
      <hardwareInterface>hardware_interface/EffortJointInterface</hardwareInterface>
    </joint>
    <actuator name="joint1_motor">
      <hardwareInterface>hardware_interface/EffortJointInterface</hardwareInterface>
      <mechanicalReduction>1</mechanicalReduction>
    </actuator>
  </transmission>
  <transmission name="joint2_tran">
    <type>transmission_interface/SimpleTransmission</type>
    <joint name="joint2">
      <hardwareInterface>hardware_interface/EffortJointInterface</hardwareInterface>
    </joint>
    <actuator name="joint2_motor">
      <hardwareInterface>hardware_interface/EffortJointInterface</hardwareInterface>
      <mechanicalReduction>-1</mechanicalReduction>
    </actuator>
  </transmission>
  <transmission name="joint3_tran">
    <type>transmission_interface/SimpleTransmission</type>
    <joint name="joint3">
      <hardwareInterface>hardware_interface/EffortJointInterface</hardwareInterface>
    </joint>
    <actuator name="joint3_motor">
      <hardwareInterface>hardware_interface/EffortJointInterface</hardwareInterface>
      <mechanicalReduction>1</mechanicalReduction>
    </actuator>
  </transmission>
  <transmission name="joint4_tran">
    <type>transmission_interface/SimpleTransmission</type>
    <joint name="joint4">
      <hardwareInterface>hardware_interface/EffortJointInterface</hardwareInterface>
    </joint>
    <actuator name="joint4_motor">
      <hardwareInterface>hardware_interface/EffortJointInterface</hardwareInterface>
      <mechanicalReduction>-1</mechanicalReduction>
    </actuator>
  </transmission>
  <transmission name="joint5_tran">
    <type>transmission_interface/SimpleTransmission</type>
    <joint name="joint5">
      <hardwareInterface>hardware_interface/EffortJointInterface</hardwareInterface>
    </joint>
    <actuator name="joint5_motor">
      <hardwareInterface>hardware_interface/EffortJointInterface</hardwareInterface>
      <mechanicalReduction>-1</mechanicalReduction>
    </actuator>
  </transmission>
  <transmission name="joint6_tran">
    <type>transmission_interface/SimpleTransmission</type>
    <joint name="joint6">
      <hardwareInterface>hardware_interface/EffortJointInterface</hardwareInterface>
    </joint>
    <actuator name="joint6_motor">
      <hardwareInterface>hardware_interface/EffortJointInterface</hardwareInterface>
      <mechanicalReduction>1</mechanicalReduction>
    </actuator>
  </transmission>
  <gazebo>
    <plugin filename="libgazebo_ros_control.so" name="gazebo_ros_control">
      <robotNamespace>/</robotNamespace>
    </plugin>
  </gazebo>
</robot>
