<?xml version="1.0" ?>
<!-- =================================================================================== -->
<!-- |    This document was autogenerated by xacro from robot.xacro                    | -->
<!-- |    EDITING THIS FILE BY HAND IS NOT RECOMMENDED                                 | -->
<!-- =================================================================================== -->
<robot name="swingarm_v2">
  <link name="world"/>
  <link name="base_link">
    <inertial>
      <origin rpy="0 0 0" xyz="0.0 0.0 0.028"/>
      <mass value="0.498"/>
      <inertia ixx="0.00027600000000000004" ixy="4.484e-08" ixz="-8.321810000000001e-07" iyy="0.0002769" iyz="1.42e-10" izz="0.000293"/>
    </inertial>
    <visual>
      <origin rpy="0 0 0" xyz="0 0 0"/>
      <geometry>
        <mesh filename="package://swingarm_v2_config/description/meshes/base_link.stl" scale="1 1 1"/>
      </geometry>
    </visual>
    <collision>
      <origin rpy="0 0 0" xyz="0 0 0"/>
      <geometry>
        <mesh filename="package://swingarm_v2_config/description/meshes/base_link.stl" scale="1 1 1"/>
      </geometry>
    </collision>
  </link>
  <link name="link1">
    <inertial>
      <origin rpy="0 0 0" xyz="0.0 -0.002 0.031"/>
      <mass value="0.432"/>
      <inertia ixx="0.00022150000000000002" ixy="7.813980000000001e-07" ixz="-7.29e-09" iyy="0.0001987" iyz="-6.728010000000001e-07" izz="0.0002012"/>
    </inertial>
    <visual>
      <origin rpy="0 0 0" xyz="0 0 0"/>
      <geometry>
        <mesh filename="package://swingarm_v2_config/description/meshes/link1.stl" scale="1 1 1"/>
      </geometry>
    </visual>
    <collision>
      <origin rpy="0 0 0" xyz="0 0 0"/>
      <geometry>
        <mesh filename="package://swingarm_v2_config/description/meshes/link1.stl" scale="1 1 1"/>
      </geometry>
    </collision>
  </link>
  <link name="link2">
    <inertial>
      <origin rpy="0 0 0" xyz="-0.055 -0.005 0.0"/>
      <mass value="0.553"/>
      <inertia ixx="0.0002747" ixy="0.0001009" ixz="-7.5e-11" iyy="0.0004359" iyz="-3.2072000000000004e-08" izz="0.0004935"/>
    </inertial>
    <visual>
      <origin rpy="0 0 0" xyz="0 0 0"/>
      <geometry>
        <mesh filename="package://swingarm_v2_config/description/meshes/link2.stl" scale="1 1 1"/>
      </geometry>
    </visual>
    <collision>
      <origin rpy="0 0 0" xyz="0 0 0"/>
      <geometry>
        <mesh filename="package://swingarm_v2_config/description/meshes/link2.stl" scale="1 1 1"/>
      </geometry>
    </collision>
  </link>
  <link name="link3">
    <inertial>
      <origin rpy="0 0 0" xyz="-0.112 0.001 -0.015"/>
      <mass value="0.952"/>
      <inertia ixx="0.0007244" ixy="4.3165882000000004e-05" ixz="0.00045200000000000004" iyy="0.003268" iyz="-2.5065069e-05" izz="0.0033360000000000004"/>
    </inertial>
    <visual>
      <origin rpy="0 0 0" xyz="0 0 0"/>
      <geometry>
        <mesh filename="package://swingarm_v2_config/description/meshes/link3.stl" scale="1 1 1"/>
      </geometry>
    </visual>
    <collision>
      <origin rpy="0 0 0" xyz="0 0 0"/>
      <geometry>
        <mesh filename="package://swingarm_v2_config/description/meshes/link3.stl" scale="1 1 1"/>
      </geometry>
    </collision>
  </link>
  <link name="link4">
    <inertial>
      <origin rpy="0 0.286 0" xyz="0.048 -0.004 0.014"/>
      <mass value="0.48"/>
      <inertia ixx="0.00025760000000000003" ixy="-8.390805400000001e-05" ixz="-3.6204464000000004e-05" iyy="0.00032520000000000004" iyz="-2.4580606000000003e-05" izz="0.00036990000000000005"/>
    </inertial>
    <visual>
      <origin rpy="0 0.286 0" xyz="0 0 0"/>
      <geometry>
        <mesh filename="package://swingarm_v2_config/description/meshes/link4.stl" scale="1 1 1"/>
      </geometry>
    </visual>
    <collision>
      <origin rpy="0 0.286 0" xyz="0 0 0"/>
      <geometry>
        <mesh filename="package://swingarm_v2_config/description/meshes/link4.stl" scale="1 1 1"/>
      </geometry>
    </collision>
  </link>
  <link name="link5">
    <inertial>
      <origin rpy="0 0 0" xyz="0.089 0.0 0.004"/>
      <mass value="0.612"/>
      <inertia ixx="0.00023640000000000003" ixy="-8.627075e-06" ixz="0.00011760000000000001" iyy="0.001082" iyz="9.8253e-07" izz="0.001077"/>
    </inertial>
    <visual>
      <origin rpy="0 0 0" xyz="0 0 0"/>
      <geometry>
        <mesh filename="package://swingarm_v2_config/description/meshes/link5.stl" scale="1 1 1"/>
      </geometry>
    </visual>
    <collision>
      <origin rpy="0 0 0" xyz="0 0 0"/>
      <geometry>
        <mesh filename="package://swingarm_v2_config/description/meshes/link5.stl" scale="1 1 1"/>
      </geometry>
    </collision>
  </link>
  <link name="link6">
    <inertial>
      <origin rpy="0 0 0" xyz="0.05 0.0 0.0"/>
      <mass value="0.484"/>
      <inertia ixx="0.00022040000000000002" ixy="-6.5970771e-05" ixz="-2.3777000000000002e-08" iyy="0.00032490000000000004" iyz="1.02795e-07" izz="0.0003573"/>
    </inertial>
    <visual>
      <origin rpy="0 0 0" xyz="0 -0.023 0"/>
      <geometry>
        <mesh filename="package://swingarm_v2_config/description/meshes/link6.stl" scale="1 1 1"/>
      </geometry>
    </visual>
    <collision>
      <origin rpy="0 0 0" xyz="0 -0.023 0"/>
      <geometry>
        <mesh filename="package://swingarm_v2_config/description/meshes/link6.stl" scale="1 1 1"/>
      </geometry>
    </collision>
  </link>
  <link name="link7">
    <inertial>
      <origin rpy="0 0 0" xyz="0.005 0.0 0.001"/>
      <mass value="0.105"/>
      <inertia ixx="2.296e-05" ixy="0.0" ixz="-5.572e-09" iyy="1.383e-05" iyz="0.0" izz="1.089e-05"/>
    </inertial>
    <visual>
      <origin rpy="0 0 0" xyz="0 0 0"/>
      <geometry>
        <mesh filename="package://swingarm_v2_config/description/meshes/link7.stl" scale="1 1 1"/>
      </geometry>
    </visual>
    <collision>
      <origin rpy="0 0 0" xyz="0 0 0"/>
      <geometry>
        <mesh filename="package://swingarm_v2_config/description/meshes/link7.stl" scale="1 1 1"/>
      </geometry>
    </collision>
  </link>
  <joint name="fixed_world" type="fixed">
    <origin rpy="0 0 0" xyz="0 0 0"/>
    <parent link="world"/>
    <child link="base_link"/>
  </joint>
  <joint name="joint1" type="revolute">
    <origin rpy="0 0 0" xyz="0 0 0.0565"/>
    <parent link="base_link"/>
    <child link="link1"/>
    <axis xyz="0 0 1"/>
    <limit effort="30" lower="-1.57" upper="1.57" velocity="1.5"/>
  </joint>
  <joint name="joint2" type="revolute">
    <origin rpy="0 0 0" xyz="0 0 0.0335"/>
    <parent link="link1"/>
    <child link="link2"/>
    <axis xyz="0 1 0"/>
    <limit effort="30" lower="0" upper="3.14" velocity="1.5"/>
  </joint>
  <joint name="joint3" type="revolute">
    <origin rpy="0 0 0" xyz="-0.095 0 0"/>
    <parent link="link2"/>
    <child link="link3"/>
    <axis xyz="1 0 0"/>
    <limit effort="30" lower="-3.14" upper="0.0" velocity="1.5"/>
  </joint>
  <joint name="joint4" type="revolute">
    <origin rpy="0 -0.286 0" xyz="-0.155 0 0"/>
    <parent link="link3"/>
    <child link="link4"/>
    <axis xyz="0 1 0"/>
    <limit effort="10" lower="-1.1" upper="0.3" velocity="1.5"/>
  </joint>
  <joint name="joint5" type="revolute">
    <origin rpy="0  0  0" xyz="0.0845 0 0"/>
    <parent link="link4"/>
    <child link="link5"/>
    <axis xyz="1 0 0"/>
    <limit effort="10" lower="-0.785" upper="0.785" velocity="1.5"/>
  </joint>
  <joint name="joint6" type="revolute">
    <origin rpy="0 0.286 0" xyz="0.1177 0 0"/>
    <parent link="link5"/>
    <child link="link6"/>
    <axis xyz="0 1 0"/>
    <limit effort="10" lower="-1.57" upper="1.57" velocity="1.5"/>
  </joint>
  <joint name="joint7" type="revolute">
    <origin rpy="0 0 0" xyz="0.0845 0 0"/>
    <parent link="link6"/>
    <child link="link7"/>
    <axis xyz="1 0 0"/>
    <limit effort="10" lower="-1.57" upper="1.57" velocity="1.5"/>
  </joint>
  <transmission name="joint1_tran">
    <type>transmission_interface/SimpleTransmission</type>
    <joint name="joint1">
      <hardwareInterface>hardware_interface/EffortJointInterface</hardwareInterface>
    </joint>
    <actuator name="joint1_motor">
      <hardwareInterface>hardware_interface/EffortJointInterface</hardwareInterface>
      <mechanicalReduction>1</mechanicalReduction>
    </actuator>
  </transmission>
  <transmission name="joint2_tran">
    <type>transmission_interface/SimpleTransmission</type>
    <joint name="joint2">
      <hardwareInterface>hardware_interface/EffortJointInterface</hardwareInterface>
    </joint>
    <actuator name="joint2_motor">
      <hardwareInterface>hardware_interface/EffortJointInterface</hardwareInterface>
      <mechanicalReduction>-1</mechanicalReduction>
    </actuator>
  </transmission>
  <transmission name="joint3_tran">
    <type>transmission_interface/SimpleTransmission</type>
    <joint name="joint3">
      <hardwareInterface>hardware_interface/EffortJointInterface</hardwareInterface>
    </joint>
    <actuator name="joint3_motor">
      <hardwareInterface>hardware_interface/EffortJointInterface</hardwareInterface>
      <mechanicalReduction>1</mechanicalReduction>
    </actuator>
  </transmission>
  <transmission name="joint4_tran">
    <type>transmission_interface/SimpleTransmission</type>
    <joint name="joint4">
      <hardwareInterface>hardware_interface/EffortJointInterface</hardwareInterface>
    </joint>
    <actuator name="joint4_motor">
      <hardwareInterface>hardware_interface/EffortJointInterface</hardwareInterface>
      <mechanicalReduction>-1</mechanicalReduction>
    </actuator>
  </transmission>
  <transmission name="joint5_tran">
    <type>transmission_interface/SimpleTransmission</type>
    <joint name="joint5">
      <hardwareInterface>hardware_interface/EffortJointInterface</hardwareInterface>
    </joint>
    <actuator name="joint5_motor">
      <hardwareInterface>hardware_interface/EffortJointInterface</hardwareInterface>
      <mechanicalReduction>-1</mechanicalReduction>
    </actuator>
  </transmission>
  <transmission name="joint6_tran">
    <type>transmission_interface/SimpleTransmission</type>
    <joint name="joint6">
      <hardwareInterface>hardware_interface/EffortJointInterface</hardwareInterface>
    </joint>
    <actuator name="joint6_motor">
      <hardwareInterface>hardware_interface/EffortJointInterface</hardwareInterface>
      <mechanicalReduction>1</mechanicalReduction>
    </actuator>
  </transmission>
  <gazebo>
    <plugin filename="libgazebo_ros_control.so" name="gazebo_ros_control">
      <robotNamespace>/</robotNamespace>
    </plugin>
  </gazebo>
</robot>
